2022-06-09 16:26:27,198 INFO    MainThread:15922 [internal.py:wandb_internal():93] W&B internal server running at pid: 15922, started at: 2022-06-09 16:26:27.197415
2022-06-09 16:26:27,201 INFO    WriterThread:15922 [datastore.py:open_for_write():75] open: /Users/zhangqiming/Desktop/RL_research/Reinforcement-Learning/project/wandb/run-20220609_162625-35vpgs2m/run-35vpgs2m.wandb
2022-06-09 16:26:27,207 DEBUG   SenderThread:15922 [sender.py:send():232] send: header
2022-06-09 16:26:27,207 DEBUG   SenderThread:15922 [sender.py:send():232] send: run
2022-06-09 16:26:55,996 DEBUG   HandlerThread:15922 [handler.py:handle_request():141] handle_request: shutdown
2022-06-09 16:26:55,997 INFO    HandlerThread:15922 [handler.py:finish():806] shutting down handler
2022-06-09 16:26:56,308 INFO    WriterThread:15922 [datastore.py:close():279] close: /Users/zhangqiming/Desktop/RL_research/Reinforcement-Learning/project/wandb/run-20220609_162625-35vpgs2m/run-35vpgs2m.wandb
2022-06-09 16:27:00,854 ERROR   SenderThread:15922 [retry.py:__call__():126] Retry attempt failed:
Traceback (most recent call last):
  File "/Users/zhangqiming/opt/anaconda3/envs/LtC/lib/python3.7/site-packages/urllib3/connection.py", line 175, in _new_conn
    (self._dns_host, self.port), self.timeout, **extra_kw
  File "/Users/zhangqiming/opt/anaconda3/envs/LtC/lib/python3.7/site-packages/urllib3/util/connection.py", line 95, in create_connection
    raise err
  File "/Users/zhangqiming/opt/anaconda3/envs/LtC/lib/python3.7/site-packages/urllib3/util/connection.py", line 85, in create_connection
    sock.connect(sa)
socket.timeout: timed out

During handling of the above exception, another exception occurred:

Traceback (most recent call last):
  File "/Users/zhangqiming/opt/anaconda3/envs/LtC/lib/python3.7/site-packages/urllib3/connectionpool.py", line 710, in urlopen
    chunked=chunked,
  File "/Users/zhangqiming/opt/anaconda3/envs/LtC/lib/python3.7/site-packages/urllib3/connectionpool.py", line 386, in _make_request
    self._validate_conn(conn)
  File "/Users/zhangqiming/opt/anaconda3/envs/LtC/lib/python3.7/site-packages/urllib3/connectionpool.py", line 1040, in _validate_conn
    conn.connect()
  File "/Users/zhangqiming/opt/anaconda3/envs/LtC/lib/python3.7/site-packages/urllib3/connection.py", line 358, in connect
    self.sock = conn = self._new_conn()
  File "/Users/zhangqiming/opt/anaconda3/envs/LtC/lib/python3.7/site-packages/urllib3/connection.py", line 182, in _new_conn
    % (self.host, self.timeout),
urllib3.exceptions.ConnectTimeoutError: (<urllib3.connection.HTTPSConnection object at 0x7fcdd2ec1350>, 'Connection to api.wandb.ai timed out. (connect timeout=10)')

During handling of the above exception, another exception occurred:

Traceback (most recent call last):
  File "/Users/zhangqiming/opt/anaconda3/envs/LtC/lib/python3.7/site-packages/requests/adapters.py", line 450, in send
    timeout=timeout
  File "/Users/zhangqiming/opt/anaconda3/envs/LtC/lib/python3.7/site-packages/urllib3/connectionpool.py", line 786, in urlopen
    method, url, error=e, _pool=self, _stacktrace=sys.exc_info()[2]
  File "/Users/zhangqiming/opt/anaconda3/envs/LtC/lib/python3.7/site-packages/urllib3/util/retry.py", line 592, in increment
    raise MaxRetryError(_pool, url, error or ResponseError(cause))
urllib3.exceptions.MaxRetryError: HTTPSConnectionPool(host='api.wandb.ai', port=443): Max retries exceeded with url: /graphql (Caused by ConnectTimeoutError(<urllib3.connection.HTTPSConnection object at 0x7fcdd2ec1350>, 'Connection to api.wandb.ai timed out. (connect timeout=10)'))

During handling of the above exception, another exception occurred:

Traceback (most recent call last):
  File "/Users/zhangqiming/opt/anaconda3/envs/LtC/lib/python3.7/site-packages/wandb/sdk/lib/retry.py", line 102, in __call__
    result = self._call_fn(*args, **kwargs)
  File "/Users/zhangqiming/opt/anaconda3/envs/LtC/lib/python3.7/site-packages/wandb/sdk/internal/internal_api.py", line 140, in execute
    return self.client.execute(*args, **kwargs)
  File "/Users/zhangqiming/opt/anaconda3/envs/LtC/lib/python3.7/site-packages/wandb/vendor/gql-0.2.0/wandb_gql/client.py", line 52, in execute
    result = self._get_result(document, *args, **kwargs)
  File "/Users/zhangqiming/opt/anaconda3/envs/LtC/lib/python3.7/site-packages/wandb/vendor/gql-0.2.0/wandb_gql/client.py", line 60, in _get_result
    return self.transport.execute(document, *args, **kwargs)
  File "/Users/zhangqiming/opt/anaconda3/envs/LtC/lib/python3.7/site-packages/wandb/vendor/gql-0.2.0/wandb_gql/transport/requests.py", line 38, in execute
    request = requests.post(self.url, **post_args)
  File "/Users/zhangqiming/opt/anaconda3/envs/LtC/lib/python3.7/site-packages/requests/api.py", line 117, in post
    return request('post', url, data=data, json=json, **kwargs)
  File "/Users/zhangqiming/opt/anaconda3/envs/LtC/lib/python3.7/site-packages/requests/api.py", line 61, in request
    return session.request(method=method, url=url, **kwargs)
  File "/Users/zhangqiming/opt/anaconda3/envs/LtC/lib/python3.7/site-packages/requests/sessions.py", line 529, in request
    resp = self.send(prep, **send_kwargs)
  File "/Users/zhangqiming/opt/anaconda3/envs/LtC/lib/python3.7/site-packages/requests/sessions.py", line 645, in send
    r = adapter.send(request, **kwargs)
  File "/Users/zhangqiming/opt/anaconda3/envs/LtC/lib/python3.7/site-packages/requests/adapters.py", line 507, in send
    raise ConnectTimeout(e, request=request)
requests.exceptions.ConnectTimeout: HTTPSConnectionPool(host='api.wandb.ai', port=443): Max retries exceeded with url: /graphql (Caused by ConnectTimeoutError(<urllib3.connection.HTTPSConnection object at 0x7fcdd2ec1350>, 'Connection to api.wandb.ai timed out. (connect timeout=10)'))
2022-06-09 16:27:08,901 INFO    SenderThread:15922 [dir_watcher.py:__init__():197] watching files in: /Users/zhangqiming/Desktop/RL_research/Reinforcement-Learning/project/wandb/run-20220609_162625-35vpgs2m/files
2022-06-09 16:27:08,901 INFO    SenderThread:15922 [sender.py:_start_run_threads():814] run started: 35vpgs2m with start time 1654806385
2022-06-09 16:27:08,901 INFO    SenderThread:15922 [sender.py:finish():1110] shutting down sender
2022-06-09 16:27:08,902 INFO    SenderThread:15922 [dir_watcher.py:finish():312] shutting down directory watcher
2022-06-09 16:27:09,906 INFO    SenderThread:15922 [dir_watcher.py:finish():342] scan: /Users/zhangqiming/Desktop/RL_research/Reinforcement-Learning/project/wandb/run-20220609_162625-35vpgs2m/files
2022-06-09 16:27:09,907 INFO    SenderThread:15922 [dir_watcher.py:finish():356] scan save: /Users/zhangqiming/Desktop/RL_research/Reinforcement-Learning/project/wandb/run-20220609_162625-35vpgs2m/files/config.yaml config.yaml
2022-06-09 16:27:09,907 INFO    SenderThread:15922 [file_pusher.py:finish():145] shutting down file pusher
2022-06-09 16:27:09,908 INFO    SenderThread:15922 [file_pusher.py:join():150] waiting for file pusher
2022-06-09 16:27:19,915 INFO    Thread-14 :15922 [upload_job.py:push():132] Uploaded file /Users/zhangqiming/Desktop/RL_research/Reinforcement-Learning/project/wandb/run-20220609_162625-35vpgs2m/files/config.yaml
2022-06-09 16:27:21,859 INFO    MainThread:15922 [internal.py:handle_exit():80] Internal process exited
