2022-06-06 14:57:13,490 INFO    MainThread:94050 [internal.py:wandb_internal():93] W&B internal server running at pid: 94050, started at: 2022-06-06 14:57:13.490361
2022-06-06 14:57:13,494 INFO    WriterThread:94050 [datastore.py:open_for_write():75] open: /Users/zhangqiming/Desktop/RL_research/Reinforcement-Learning/project/wandb/run-20220606_145712-12jalqcz/run-12jalqcz.wandb
2022-06-06 14:57:13,497 DEBUG   SenderThread:94050 [sender.py:send():232] send: header
2022-06-06 14:57:13,497 DEBUG   SenderThread:94050 [sender.py:send():232] send: run
2022-06-06 14:57:13,650 ERROR   SenderThread:94050 [internal_api.py:execute():143] 404 response executing GraphQL.
2022-06-06 14:57:13,650 ERROR   SenderThread:94050 [internal_api.py:execute():144] {"errors":[{"message":"project not found","path":["upsertBucket"]}],"data":{"upsertBucket":null}}
2022-06-06 14:57:14,496 INFO    HandlerThread:94050 [handler.py:finish():806] shutting down handler
2022-06-06 14:57:14,500 INFO    WriterThread:94050 [datastore.py:close():279] close: /Users/zhangqiming/Desktop/RL_research/Reinforcement-Learning/project/wandb/run-20220606_145712-12jalqcz/run-12jalqcz.wandb
2022-06-06 14:57:14,500 ERROR   MainThread:94050 [internal.py:wandb_internal():165] Thread SenderThread:
Traceback (most recent call last):
  File "/Users/zhangqiming/opt/anaconda3/envs/LtC/lib/python3.7/site-packages/wandb/sdk/lib/retry.py", line 102, in __call__
    result = self._call_fn(*args, **kwargs)
  File "/Users/zhangqiming/opt/anaconda3/envs/LtC/lib/python3.7/site-packages/wandb/sdk/internal/internal_api.py", line 140, in execute
    return self.client.execute(*args, **kwargs)
  File "/Users/zhangqiming/opt/anaconda3/envs/LtC/lib/python3.7/site-packages/wandb/vendor/gql-0.2.0/wandb_gql/client.py", line 52, in execute
    result = self._get_result(document, *args, **kwargs)
  File "/Users/zhangqiming/opt/anaconda3/envs/LtC/lib/python3.7/site-packages/wandb/vendor/gql-0.2.0/wandb_gql/client.py", line 60, in _get_result
    return self.transport.execute(document, *args, **kwargs)
  File "/Users/zhangqiming/opt/anaconda3/envs/LtC/lib/python3.7/site-packages/wandb/vendor/gql-0.2.0/wandb_gql/transport/requests.py", line 39, in execute
    request.raise_for_status()
  File "/Users/zhangqiming/opt/anaconda3/envs/LtC/lib/python3.7/site-packages/requests/models.py", line 960, in raise_for_status
    raise HTTPError(http_error_msg, response=self)
requests.exceptions.HTTPError: 404 Client Error: Not Found for url: https://api.wandb.ai/graphql

During handling of the above exception, another exception occurred:

Traceback (most recent call last):
  File "/Users/zhangqiming/opt/anaconda3/envs/LtC/lib/python3.7/site-packages/wandb/apis/normalize.py", line 22, in wrapper
    return func(*args, **kwargs)
  File "/Users/zhangqiming/opt/anaconda3/envs/LtC/lib/python3.7/site-packages/wandb/sdk/internal/internal_api.py", line 1319, in upsert_run
    response = self.gql(mutation, variable_values=variable_values, **kwargs)
  File "/Users/zhangqiming/opt/anaconda3/envs/LtC/lib/python3.7/site-packages/wandb/sdk/lib/retry.py", line 118, in __call__
    if not check_retry_fn(e):
  File "/Users/zhangqiming/opt/anaconda3/envs/LtC/lib/python3.7/site-packages/wandb/util.py", line 882, in no_retry_auth
    raise CommError("Permission denied, ask the project owner to grant you access")
wandb.errors.CommError: Permission denied, ask the project owner to grant you access

During handling of the above exception, another exception occurred:

Traceback (most recent call last):
  File "/Users/zhangqiming/opt/anaconda3/envs/LtC/lib/python3.7/site-packages/wandb/sdk/internal/internal_util.py", line 51, in run
    self._run()
  File "/Users/zhangqiming/opt/anaconda3/envs/LtC/lib/python3.7/site-packages/wandb/sdk/internal/internal_util.py", line 102, in _run
    self._process(record)
  File "/Users/zhangqiming/opt/anaconda3/envs/LtC/lib/python3.7/site-packages/wandb/sdk/internal/internal.py", line 310, in _process
    self._sm.send(record)
  File "/Users/zhangqiming/opt/anaconda3/envs/LtC/lib/python3.7/site-packages/wandb/sdk/internal/sender.py", line 234, in send
    send_handler(record)
  File "/Users/zhangqiming/opt/anaconda3/envs/LtC/lib/python3.7/site-packages/wandb/sdk/internal/sender.py", line 692, in send_run
    self._init_run(run, config_value_dict)
  File "/Users/zhangqiming/opt/anaconda3/envs/LtC/lib/python3.7/site-packages/wandb/sdk/internal/sender.py", line 730, in _init_run
    commit=run.git.last_commit or None,
  File "/Users/zhangqiming/opt/anaconda3/envs/LtC/lib/python3.7/site-packages/wandb/apis/normalize.py", line 58, in wrapper
    raise CommError(message, err).with_traceback(sys.exc_info()[2])
  File "/Users/zhangqiming/opt/anaconda3/envs/LtC/lib/python3.7/site-packages/wandb/apis/normalize.py", line 22, in wrapper
    return func(*args, **kwargs)
  File "/Users/zhangqiming/opt/anaconda3/envs/LtC/lib/python3.7/site-packages/wandb/sdk/internal/internal_api.py", line 1319, in upsert_run
    response = self.gql(mutation, variable_values=variable_values, **kwargs)
  File "/Users/zhangqiming/opt/anaconda3/envs/LtC/lib/python3.7/site-packages/wandb/sdk/lib/retry.py", line 118, in __call__
    if not check_retry_fn(e):
  File "/Users/zhangqiming/opt/anaconda3/envs/LtC/lib/python3.7/site-packages/wandb/util.py", line 882, in no_retry_auth
    raise CommError("Permission denied, ask the project owner to grant you access")
wandb.errors.CommError: Permission denied, ask the project owner to grant you access
2022-06-06 14:57:16,524 INFO    MainThread:94050 [internal.py:handle_exit():80] Internal process exited
